<?xml version="1.0"?>
<robot name="rbda">
  <!-- Links -->
  <link name="world"/>

  <link name="mobile_base">
    <inertial>
      <mass value="161"/>
      <origin rpy="0 0 0" xyz="0.0 0.0 0.0"/>
      <inertia ixx="27" ixy="-0.007" ixz="-0.612" iyy="23" iyz="-4.439" izz="10.129"/>
    </inertial>

    <visual>
      <geometry>
        <mesh filename="package://rbda_description/meshes/MOBILE_BASE.stl"/>
      </geometry>
      <material name="LightGrey">
        <color rgba="0.7 0.7 0.7 1.0"/>
      </material>
    </visual>
  </link>

  <link name="base">
    <inertial>
      <mass value="2.91800"/>
      <origin rpy="0 0 0" xyz="0.0 0.0 0.0"/>
      <inertia ixx="0.01457529" ixy="-0.00000082" ixz="0.00054762" iyy="0.01518894" iyz="0.00000058" izz="0.01550123"/>
    </inertial>

    <visual>
      <geometry>
        <mesh filename="package://rbda_description/meshes/BASE.stl" scale="0.001 0.001 0.001"/>
      </geometry>
      <material name="LightGrey">
        <color rgba="0.7 0.7 0.7 1.0"/>
      </material>
    </visual>
  </link>

  <link name="link_0">
    <inertial>
      <mass value="11.64466333"/>
      <origin rpy="0 0 0" xyz="0.0 0.0 0.0"/>
      <inertia ixx=" 0.45161787" ixy="0.00000094" ixz="0.00028876" iyy="0.43572041" iyz="-0.00050430" izz="0.05408588"/>
    </inertial>

    <visual>
      <geometry>
        <mesh filename="package://rbda_description/meshes/LINK_0.stl" scale="0.001 0.001 0.001"/>
      </geometry>
      <material name="LightGrey">
        <color rgba="0.7 0.7 0.7 1.0"/>
      </material>
    </visual>
  </link>

  <link name="link_1">
    <inertial>
      <mass value="13.25377205"/>
      <origin rpy="0 0 0" xyz="0.0 0.0 0.0"/>
      <inertia ixx="0.19474508" ixy="0.00001690" ixz="-0.00000023" iyy="0.17137211" iyz="-0.00049213" izz="0.06527313"/>
    </inertial>

    <visual>
      <geometry>
        <mesh filename="package://rbda_description/meshes/LINK_1.stl" scale="0.001 0.001 0.001"/>
      </geometry>
      <material name="LightGrey">
        <color rgba="0.7 0.7 0.7 1.0"/>
      </material>
    </visual>
  </link>

  <link name="link_2">
    <inertial>
      <mass value="13.33042487"/>
      <origin rpy="0 0 0" xyz="0.0 0.0 0.0"/>
      <inertia ixx="0.15616959" ixy="0.00001687" ixz="0.00092799" iyy="0.13607163" iyz="-0.00105443" izz="0.05910817"/>
    </inertial>

    <visual>
      <geometry>
        <mesh filename="package://rbda_description/meshes/LINK_2.stl" scale="0.001 0.001 0.001"/>
      </geometry>
      <material name="LightGrey">
        <color rgba="0.7 0.7 0.7 1.0"/>
      </material>
    </visual>
  </link>

  <link name="link_3">
    <inertial>
      <mass value="2.07669726"/>
      <origin rpy="0 0 0" xyz="0.0 0.0 0.0"/>
      <inertia ixx="0.00414408" ixy="-0.00000026" ixz="-0.00000377" iyy="0.00414761" iyz="-0.00001979" izz="0.00215831"/>
    </inertial>

    <visual>
      <geometry>
        <mesh filename="package://rbda_description/meshes/LINK_3.stl" scale="0.001 0.001 0.001"/>
      </geometry>
      <material name="LightGrey">
        <color rgba="0.7 0.7 0.7 1.0"/>
      </material>
    </visual>
  </link>

  <link name="link_4">
    <inertial>
      <mass value="4.08159704"/>
      <origin rpy="0 0 0" xyz="0.0 0.0 0.0"/>
      <inertia ixx="0.17216619" ixy="-0.00002462" ixz="-0.00000840" iyy="0.13459627" iyz="0.04730580" izz="0.04149886"/>
    </inertial>

    <visual>
      <geometry>
        <mesh filename="package://rbda_description/meshes/LINK_4.stl" scale="0.001 0.001 0.001"/>
      </geometry>
      <material name="LightGrey">
        <color rgba="0.7 0.7 0.7 1.0"/>
      </material>
    </visual>
  </link>

  <link name="link_5">
    <inertial>
      <mass value="1.50221027"/>
      <origin rpy="0 0 0" xyz="0.0 0.0 0.0"/>
      <inertia ixx="0.00265085" ixy="0.00000064" ixz="-0.00000260" iyy="0.00257202" iyz="0.00002846" izz="0.00128540"/>
    </inertial>

    <visual>
      <geometry>
        <mesh filename="package://rbda_description/meshes/LINK_5.stl" scale="0.001 0.001 0.001"/>
      </geometry>
      <material name="LightGrey">
        <color rgba="0.7 0.7 0.7 1.0"/>
      </material>
    </visual>
  </link>

  <link name="link_6">
    <inertial>
      <mass value="1.72019885"/>
      <origin rpy="0 0 0" xyz="0.0 0.0 0.0"/>
      <inertia ixx="0.14995915" ixy="0.00000873" ixz="-0.00002574" iyy="0.14118611" iyz="0.03306523" izz="0.00998350"/>
    </inertial>

    <visual>
      <geometry>
        <mesh filename="package://rbda_description/meshes/LINK_6.stl" scale="0.001 0.001 0.001"/>
      </geometry>
      <material name="LightGrey">
        <color rgba="0.7 0.7 0.7 1.0"/>
      </material>
    </visual>
  </link>

  <link name="link_7">
    <inertial>
      <mass value="0.88877220"/>
      <origin rpy="0 0 0" xyz="0.0 0.0 0.0"/>
      <inertia ixx="0.00106944" ixy="-0.00000027" ixz="-0.00000260" iyy="0.00105709" iyz="0.00000295" izz="0.00045001"/>
    </inertial>

    <visual>
      <geometry>
        <mesh filename="package://rbda_description/meshes/LINK_7.stl" scale="0.001 0.001 0.001"/>
      </geometry>
      <material name="LightGrey">
        <color rgba="0.7 0.7 0.7 1.0"/>
      </material>
    </visual>
  </link>

  <link name="link_8">
    <inertial>
      <mass value="0.04971115"/>
      <origin rpy="0 0 0" xyz="0.0 0.0 0.0"/>
      <inertia ixx="0.00025591" ixy="-0.00000040" ixz="0.00000373" iyy="0.00024646" iyz="0.00000444" izz="0.00003526"/>
    </inertial>

    <visual>
      <geometry>
        <mesh filename="package://rbda_description/meshes/LINK_8.stl" scale="0.001 0.001 0.001"/>
      </geometry>
      <material name="LightGrey">
        <color rgba="0.7 0.7 0.7 1.0"/>
      </material>
    </visual>
  </link>

  <link name="link_10">
    <inertial>
      <mass value="2.07669726"/>
      <origin rpy="0 0 0" xyz="0.0 0.0 0.0"/>
      <inertia ixx="0.00414408" ixy="-0.00000026" ixz="0.00000377" iyy="0.00414761" iyz="0.00001979" izz="0.00215831"/>
    </inertial>

    <visual>
      <geometry>
        <mesh filename="package://rbda_description/meshes/LINK_10.stl" scale="0.001 0.001 0.001"/>
      </geometry>
      <material name="LightGrey">
        <color rgba="0.7 0.7 0.7 1.0"/>
      </material>
    </visual>
  </link>

  <link name="link_11">
    <inertial>
      <mass value="4.08159704"/>
      <origin rpy="0 0 0" xyz="0.0 0.0 0.0"/>
      <inertia ixx="0.17216619" ixy="-0.00002462" ixz="0.00000840" iyy="0.13459627" iyz="-0.04730580" izz="0.04149886"/>
    </inertial>

    <visual>
      <geometry>
        <mesh filename="package://rbda_description/meshes/LINK_11.stl" scale="0.001 0.001 0.001"/>
      </geometry>
      <material name="LightGrey">
        <color rgba="0.7 0.7 0.7 1.0"/>
      </material>
    </visual>
  </link>

  <link name="link_12">
    <inertial>
      <mass value="1.50221027"/>
      <origin rpy="0 0 0" xyz="0.0 0.0 0.0"/>
      <inertia ixx="0.00265085" ixy="0.00000064" ixz="0.00000260" iyy="0.00257202" iyz="-0.00002846" izz="0.00128540"/>
    </inertial>

    <visual>
      <geometry>
        <mesh filename="package://rbda_description/meshes/LINK_12.stl" scale="0.001 0.001 0.001"/>
      </geometry>
      <material name="LightGrey">
        <color rgba="0.7 0.7 0.7 1.0"/>
      </material>
    </visual>
  </link>

  <link name="link_13">
    <inertial>
      <mass value="1.72019885"/>
      <origin rpy="0 0 0" xyz="0.0 0.0 0.0"/>
      <inertia ixx="0.14995915" ixy="0.00000873" ixz="0.00002574" iyy="0.14118611" iyz="-0.03306523" izz="0.00998350"/>
    </inertial>

    <visual>
      <geometry>
        <mesh filename="package://rbda_description/meshes/LINK_13.stl" scale="0.001 0.001 0.001"/>
      </geometry>
      <material name="LightGrey">
        <color rgba="0.7 0.7 0.7 1.0"/>
      </material>
    </visual>
  </link>

  <link name="link_14">
    <inertial>
      <mass value="0.88877220"/>
      <origin rpy="0 0 0" xyz="0.0 0.0 0.0"/>
      <inertia ixx="0.00106944" ixy="-0.00000027" ixz="0.00000260" iyy="0.00105709" iyz="-0.00000295" izz="0.00045001"/>
    </inertial>

    <visual>
      <geometry>
        <mesh filename="package://rbda_description/meshes/LINK_14.stl" scale="0.001 0.001 0.001"/>
      </geometry>
      <material name="LightGrey">
        <color rgba="0.7 0.7 0.7 1.0"/>
      </material>
    </visual>
  </link>

  <link name="link_15">
    <inertial>
      <mass value="0.88877220"/>
      <origin rpy="0 0 0" xyz="0.0 0.0 0.0"/>
      <inertia ixx="0.00106944" ixy="-0.00000027" ixz="0.00000260" iyy="0.00105709" iyz="-0.00000295" izz="0.00045001"/>
    </inertial>

    <visual>
      <geometry>
        <mesh filename="package://rbda_description/meshes/LINK_15.stl" scale="0.001 0.001 0.001"/>
      </geometry>
      <material name="LightGrey">
        <color rgba="0.7 0.7 0.7 1.0"/>
      </material>
    </visual>
  </link>

  <!-- Joints -->
  <joint name="world_joint" type="continuous">
    <parent link="world"/>
    <child link="mobile_base"/>
    <origin rpy="0.0 0.0 0.0" xyz="0.0 0.0 0.0"/>
    <axis xyz="0 0 1"/>
  </joint>

  <joint name="base_joint" type="fixed">
    <parent link="mobile_base"/>
    <child link="base"/>
    <origin rpy="0.0 0.0 0.0" xyz="0.0 0.0 0.0"/>
  </joint>

  <joint name="joint_0" type="continuous">
    <parent link="base"/>
    <child link="link_0"/>
    <origin rpy="0.0 0.0 0.0" xyz="0.0 0.0 0.36000"/>
    <axis xyz="0 0 1"/>
  </joint>

  <joint name="joint_1" type="continuous">
    <parent link="link_0"/>
    <child link="link_1"/>
    <origin rpy="0.0 0.0 0.0" xyz="0.0 0.0 0.0"/>
    <axis xyz="0 1 0"/>
  </joint>

  <joint name="joint_2" type="continuous">
    <parent link="link_1"/>
    <child link="link_2"/>
    <origin rpy="0.0 0.0 0.0" xyz="0.0 0.0 0.266"/>
    <axis xyz="0 1 0"/>
  </joint>

  <joint name="joint_3" type="continuous">
    <parent link="link_2"/>
    <child link="link_3"/>
    <origin rpy="0.0 0.0 0.0" xyz="0.0 -0.10000 0.26280"/>
    <axis xyz="0 0 1"/>
  </joint>

  <joint name="joint_4" type="continuous">
    <parent link="link_3"/>
    <child link="link_4"/>
    <origin rpy="0.0 0.0 0.0" xyz="0.0 0.0 0.0"/>
    <axis xyz="0 1 0"/>
  </joint>

  <joint name="joint_5" type="continuous">
    <parent link="link_4"/>
    <child link="link_5"/>
    <origin rpy="0.0 0.0 0.0" xyz="0.0 -0.00645 0.28600"/>
    <axis xyz="0 1 0"/>
  </joint>

  <joint name="joint_6" type="continuous">
    <parent link="link_5"/>
    <child link="link_6"/>
    <origin rpy="0.0 0.0 0.0" xyz="0.0 0.0 -0.005"/>
    <axis xyz="0 0 1"/>
  </joint>

  <joint name="joint_7" type="continuous">
    <parent link="link_6"/>
    <child link="link_7"/>
    <origin rpy="0.0 0.0 0.0" xyz="0.0 0.0 0.34900"/>
    <axis xyz="0 1 0"/>
  </joint>

  <joint name="joint_8" type="continuous">
    <parent link="link_7"/>
    <child link="link_8"/>
    <origin rpy="0.0 0.0 0.0" xyz="0.0 0.0 0.0"/>
    <axis xyz="0 0 1"/>
  </joint>

  <joint name="joint_10" type="continuous">
    <parent link="link_2"/>
    <child link="link_10"/>
    <origin rpy="0.0 0.0 0.0" xyz="0.0 0.10000 0.26280"/>
    <axis xyz="0 0 1"/>
  </joint>

  <joint name="joint_11" type="continuous">
    <parent link="link_10"/>
    <child link="link_11"/>
    <origin rpy="0.0 0.0 0.0" xyz="0.0 0.0 0.0"/>
    <axis xyz="0 1 0"/>
  </joint>

  <joint name="joint_12" type="continuous">
    <parent link="link_11"/>
    <child link="link_12"/>
    <origin rpy="0.0 0.0 0.0" xyz="0.0 0.00645 0.28600"/>
    <axis xyz="0 1 0"/>
  </joint>

  <joint name="joint_13" type="continuous">
    <parent link="link_12"/>
    <child link="link_13"/>
    <origin rpy="0.0 0.0 0.0" xyz="0.0 0.0 -0.005"/>
    <axis xyz="0 0 1"/>
  </joint>

  <joint name="joint_14" type="continuous">
    <parent link="link_13"/>
    <child link="link_14"/>
    <origin rpy="0.0 0.0 0.0" xyz="0.0 0.0 0.34900"/>
    <axis xyz="0 1 0"/>
  </joint>

  <joint name="joint_15" type="continuous">
    <parent link="link_14"/>
    <child link="link_15"/>
    <origin rpy="0.0 0.0 0.0" xyz="0.0 0.0 0.0"/>
    <axis xyz="0 0 1"/>
  </joint>
</robot>