<?xml version="1.0"?>
<robot name="rbda">
  <!-- Links -->
  <link name="world"/>

  <link name="mobile_base">
    <inertial>
      <mass value="161"/>
      <origin rpy="0 0 0" xyz="0.0 0.0 0.0"/>
      <inertia ixx="27" ixy="-0.007" ixz="-0.612" iyy="23" iyz="-4.439" izz="10.129"/>
    </inertial>

    <visual>
      <geometry>
        <mesh filename="package://rbda_description/meshes/MOBILE_BASE.stl"/>
      </geometry>
      <material name="LightGrey">
        <color rgba="0.7 0.7 0.7 1.0"/>
      </material>
    </visual>
  </link>

  <link name="base">
    <inertial>
      <mass value="2.91800"/>
      <origin rpy="0 0 0" xyz="-0.00673318 -0.00000281 0.04165169"/>
      <inertia ixx="0.00951296" ixy="-0.00000076" ixz="-0.00027073" iyy="0.00999431" iyz="0.00000024" izz="0.01536894"/>
    </inertial>

    <visual>
      <geometry>
        <mesh filename="package://rbda_description/meshes/BASE.stl" scale="0.001 0.001 0.001"/>
      </geometry>
      <material name="LightGrey">
        <color rgba="0.7 0.7 0.7 1.0"/>
      </material>
    </visual>
  </link>

  <link name="link_0">
    <inertial>
      <mass value="11.64466333"/>
      <origin rpy="0 0 0" xyz="0.00019601 -0.00010424 -0.17440623"/>
      <inertia ixx="0.09741581" ixy="0.00000071" ixz="-0.00010932" iyy="0.08151803" iyz="-0.00029259" izz="0.05408530"/>
    </inertial>

    <visual>
      <geometry>
        <mesh filename="package://rbda_description/meshes/LINK_0.stl" scale="0.001 0.001 0.001"/>
      </geometry>
      <material name="LightGrey">
        <color rgba="0.7 0.7 0.7 1.0"/>
      </material>
    </visual>
  </link>

  <link name="link_1">
    <inertial>
      <mass value="13.25377205"/>
      <origin rpy="0 0 0" xyz="0.00000595 0.01281610 0.05448426"/>
      <inertia ixx="0.15322384" ixy="0.00001791" ixz="0.00000407" iyy="0.13202783" iyz="0.00876265" izz="0.06309617"/>
    </inertial>

    <visual>
      <geometry>
        <mesh filename="package://rbda_description/meshes/LINK_1.stl" scale="0.001 0.001 0.001"/>
      </geometry>
      <material name="LightGrey">
        <color rgba="0.7 0.7 0.7 1.0"/>
      </material>
    </visual>
  </link>

  <link name="link_2">
    <inertial>
      <mass value="13.33042487"/>
      <origin rpy="0 0 0" xyz="-0.00026147 0.01349281 0.04899286"/>
      <inertia ixx="0.12174569" ixy="-0.00003016" ixz="0.00075722" iyy="0.10407370" iyz="0.00775766" izz="0.05668038"/>
    </inertial>

    <visual>
      <geometry>
        <mesh filename="package://rbda_description/meshes/LINK_2.stl" scale="0.001 0.001 0.001"/>
      </geometry>
      <material name="LightGrey">
        <color rgba="0.7 0.7 0.7 1.0"/>
      </material>
    </visual>
  </link>

  <link name="link_3">
    <inertial>
      <mass value="2.07669726"/>
      <origin rpy="0 0 0" xyz="0.00010983 -0.00283683 -0.02641148"/>
      <inertia ixx="0.00267874" ixy="-0.00000091" ixz="-0.00000979" iyy="0.00269895" iyz="0.00013581" izz="0.00214157"/>
    </inertial>

    <visual>
      <geometry>
        <mesh filename="package://rbda_description/meshes/LINK_3.stl" scale="0.001 0.001 0.001"/>
      </geometry>
      <material name="LightGrey">
        <color rgba="0.7 0.7 0.7 1.0"/>
      </material>
    </visual>
  </link>

  <link name="link_4">
    <inertial>
      <mass value="4.08159704"/>
      <origin rpy="0 0 0" xyz="-0.00004900 -0.09435644 0.12178684"/>
      <inertia ixx="0.07528878" ixy="-0.00000575" ixz="-0.00003275" iyy="0.07405787" iyz="0.00040265" izz="0.00515983"/>
    </inertial>

    <visual>
      <geometry>
        <mesh filename="package://rbda_description/meshes/LINK_4.stl" scale="0.001 0.001 0.001"/>
      </geometry>
      <material name="LightGrey">
        <color rgba="0.7 0.7 0.7 1.0"/>
      </material>
    </visual>
  </link>

  <link name="link_5">
    <inertial>
      <mass value="1.50221027"/>
      <origin rpy="0 0 0" xyz="-0.00001940 -0.00385360 0.02546944"/>
      <inertia ixx="0.00165407" ixy="0.00000075" ixz="-0.00000334" iyy="0.00159755" iyz="-0.00011898" izz="0.00126310"/>
    </inertial>

    <visual>
      <geometry>
        <mesh filename="package://rbda_description/meshes/LINK_5.stl" scale="0.001 0.001 0.001"/>
      </geometry>
      <material name="LightGrey">
        <color rgba="0.7 0.7 0.7 1.0"/>
      </material>
    </visual>
  </link>

  <link name="link_6">
    <inertial>
      <mass value="1.72019885"/>
      <origin rpy="0 0 0" xyz="0.00004231 -0.06401754 0.26361598"/>
      <inertia ixx="0.01878919" ixy="0.00000407" ixz="-0.00000619" iyy="0.01706594" iyz="0.00348446" izz="0.00293370"/>
    </inertial>

    <visual>
      <geometry>
        <mesh filename="package://rbda_description/meshes/LINK_6.stl" scale="0.001 0.001 0.001"/>
      </geometry>
      <material name="LightGrey">
        <color rgba="0.7 0.7 0.7 1.0"/>
      </material>
    </visual>
  </link>

  <link name="link_7">
    <inertial>
      <mass value="0.88877220"/>
      <origin rpy="0 0 0" xyz="-0.00009323 -0.00153432 0.02224945"/>
      <inertia ixx="0.00062738" ixy="-0.00000014" ixz="-0.00000444" iyy="0.00061711" iyz="-0.00002739" izz="0.00044791"/>
    </inertial>

    <visual>
      <geometry>
        <mesh filename="package://rbda_description/meshes/LINK_7.stl" scale="0.001 0.001 0.001"/>
      </geometry>
      <material name="LightGrey">
        <color rgba="0.7 0.7 0.7 1.0"/>
      </material>
    </visual>
  </link>

  <link name="link_8">
    <inertial>
      <mass value="0.04971115"/>
      <origin rpy="0 0 0" xyz="-0.00097028 -0.00127066 0.06795755"/>
      <inertia ixx="0.00002625" ixy="-0.00000034" ixz="0.00000046" iyy="0.00001684" iyz="0.00000015" izz="0.00003513"/>
    </inertial>

    <visual>
      <geometry>
        <mesh filename="package://rbda_description/meshes/LINK_8.stl" scale="0.001 0.001 0.001"/>
      </geometry>
      <material name="LightGrey">
        <color rgba="0.7 0.7 0.7 1.0"/>
      </material>
    </visual>
  </link>

  <link name="link_10">
    <inertial>
      <mass value="2.07669726"/>
      <origin rpy="0 0 0" xyz="-0.00010983 0.00283683 -0.02641148"/>
      <inertia ixx="0.00267874" ixy="-0.00000091" ixz="0.00000979" iyy="0.00269895" iyz="-0.00013581" izz="0.00214157"/>
    </inertial>

    <visual>
      <geometry>
        <mesh filename="package://rbda_description/meshes/LINK_10.stl" scale="0.001 0.001 0.001"/>
      </geometry>
      <material name="LightGrey">
        <color rgba="0.7 0.7 0.7 1.0"/>
      </material>
    </visual>
  </link>

  <link name="link_11">
    <inertial>
      <mass value="4.08159704"/>
      <origin rpy="0 0 0" xyz="0.00004900 0.09435644 0.12178684"/>
      <inertia ixx="0.07528878" ixy="-0.00000575" ixz="0.00003275" iyy="0.07405787" iyz="-0.00040265" izz="0.00515983"/>
    </inertial>

    <visual>
      <geometry>
        <mesh filename="package://rbda_description/meshes/LINK_11.stl" scale="0.001 0.001 0.001"/>
      </geometry>
      <material name="LightGrey">
        <color rgba="0.7 0.7 0.7 1.0"/>
      </material>
    </visual>
  </link>

  <link name="link_12">
    <inertial>
      <mass value="1.50221027"/>
      <origin rpy="0 0 0" xyz="0.00001940 0.00385360 0.02546944"/>
      <inertia ixx="0.00165407" ixy="0.00000075" ixz="0.00000334" iyy="0.00159755" iyz="0.00011898" izz="0.00126310"/>
    </inertial>

    <visual>
      <geometry>
        <mesh filename="package://rbda_description/meshes/LINK_12.stl" scale="0.001 0.001 0.001"/>
      </geometry>
      <material name="LightGrey">
        <color rgba="0.7 0.7 0.7 1.0"/>
      </material>
    </visual>
  </link>

  <link name="link_13">
    <inertial>
      <mass value="1.72019885"/>
      <origin rpy="0 0 0" xyz="-0.00004231 0.06401754 0.26361598"/>
      <inertia ixx="0.01878919" ixy="0.00000407" ixz="0.00000619" iyy="0.01706594" iyz="-0.00348446" izz="0.00293370"/>
    </inertial>

    <visual>
      <geometry>
        <mesh filename="package://rbda_description/meshes/LINK_13.stl" scale="0.001 0.001 0.001"/>
      </geometry>
      <material name="LightGrey">
        <color rgba="0.7 0.7 0.7 1.0"/>
      </material>
    </visual>
  </link>

  <link name="link_14">
    <inertial>
      <mass value="0.88877220"/>
      <origin rpy="0 0 0" xyz="0.00009323 0.00153432 0.02224945"/>
      <inertia ixx="0.00062738" ixy="-0.00000014" ixz="0.00000444" iyy="0.00061711" iyz="0.00002739" izz="0.00044791"/>
    </inertial>

    <visual>
      <geometry>
        <mesh filename="package://rbda_description/meshes/LINK_14.stl" scale="0.001 0.001 0.001"/>
      </geometry>
      <material name="LightGrey">
        <color rgba="0.7 0.7 0.7 1.0"/>
      </material>
    </visual>
  </link>

  <link name="link_15">
    <inertial>
      <mass value="0.88877220"/>
      <origin rpy="0 0 0" xyz="0.00097028 0.00127066 0.06795755"/>
      <inertia ixx="0.00002625" ixy="-0.00000034" ixz="-0.00000046" iyy="0.00001684" iyz="-0.00000015" izz="0.00003513"/>
    </inertial>

    <visual>
      <geometry>
        <mesh filename="package://rbda_description/meshes/LINK_15.stl" scale="0.001 0.001 0.001"/>
      </geometry>
      <material name="LightGrey">
        <color rgba="0.7 0.7 0.7 1.0"/>
      </material>
    </visual>
  </link>

  <!-- Joints -->
  <joint name="world_joint" type="continuous">
    <parent link="world"/>
    <child link="mobile_base"/>
    <origin rpy="0.0 0.0 0.0" xyz="0.0 0.0 0.0"/>
    <axis xyz="0 0 1"/>
  </joint>

  <joint name="base_joint" type="fixed">
    <parent link="mobile_base"/>
    <child link="base"/>
    <origin rpy="0.0 0.0 0.0" xyz="0.0 0.0 0.0"/>
  </joint>

  <joint name="joint_0" type="continuous">
    <parent link="base"/>
    <child link="link_0"/>
    <origin rpy="0.0 0.0 0.0" xyz="0.0 0.0 0.36000"/>
    <axis xyz="0 0 1"/>
  </joint>

  <joint name="joint_1" type="continuous">
    <parent link="link_0"/>
    <child link="link_1"/>
    <origin rpy="0.0 0.0 0.0" xyz="0.0 0.0 0.0"/>
    <axis xyz="0 1 0"/>
  </joint>

  <joint name="joint_2" type="continuous">
    <parent link="link_1"/>
    <child link="link_2"/>
    <origin rpy="0.0 0.0 0.0" xyz="0.0 0.0 0.266"/>
    <axis xyz="0 1 0"/>
  </joint>

  <joint name="joint_3" type="continuous">
    <parent link="link_2"/>
    <child link="link_3"/>
    <origin rpy="0.0 0.0 0.0" xyz="0.0 -0.10000 0.26280"/>
    <axis xyz="0 0 1"/>
  </joint>

  <joint name="joint_4" type="continuous">
    <parent link="link_3"/>
    <child link="link_4"/>
    <origin rpy="0.0 0.0 0.0" xyz="0.0 0.0 0.0"/>
    <axis xyz="0 1 0"/>
  </joint>

  <joint name="joint_5" type="continuous">
    <parent link="link_4"/>
    <child link="link_5"/>
    <origin rpy="0.0 0.0 0.0" xyz="0.0 -0.00645 0.28600"/>
    <axis xyz="0 1 0"/>
  </joint>

  <joint name="joint_6" type="continuous">
    <parent link="link_5"/>
    <child link="link_6"/>
    <origin rpy="0.0 0.0 0.0" xyz="0.0 0.0 0.0"/>
    <axis xyz="0 0 1"/>
  </joint>

  <joint name="joint_7" type="continuous">
    <parent link="link_6"/>
    <child link="link_7"/>
    <origin rpy="0.0 0.0 0.0" xyz="0.0 0.0 0.34400"/>
    <axis xyz="0 1 0"/>
  </joint>

  <joint name="joint_8" type="continuous">
    <parent link="link_7"/>
    <child link="link_8"/>
    <origin rpy="0.0 0.0 0.0" xyz="0.0 0.0 0.0"/>
    <axis xyz="0 0 1"/>
  </joint>

  <joint name="joint_10" type="continuous">
    <parent link="link_2"/>
    <child link="link_10"/>
    <origin rpy="0.0 0.0 0.0" xyz="0.0 0.10000 0.26280"/>
    <axis xyz="0 0 1"/>
  </joint>

  <joint name="joint_11" type="continuous">
    <parent link="link_10"/>
    <child link="link_11"/>
    <origin rpy="0.0 0.0 0.0" xyz="0.0 0.0 0.0"/>
    <axis xyz="0 1 0"/>
  </joint>

  <joint name="joint_12" type="continuous">
    <parent link="link_11"/>
    <child link="link_12"/>
    <origin rpy="0.0 0.0 0.0" xyz="0.0 0.00645 0.28600"/>
    <axis xyz="0 1 0"/>
  </joint>

  <joint name="joint_13" type="continuous">
    <parent link="link_12"/>
    <child link="link_13"/>
    <origin rpy="0.0 0.0 0.0" xyz="0.0 0.0 0.0"/>
    <axis xyz="0 0 1"/>
  </joint>

  <joint name="joint_14" type="continuous">
    <parent link="link_13"/>
    <child link="link_14"/>
    <origin rpy="0.0 0.0 0.0" xyz="0.0 0.0 0.34400"/>
    <axis xyz="0 1 0"/>
  </joint>

  <joint name="joint_15" type="continuous">
    <parent link="link_14"/>
    <child link="link_15"/>
    <origin rpy="0.0 0.0 0.0" xyz="0.0 0.0 0.0"/>
    <axis xyz="0 0 1"/>
  </joint>
</robot>